<sdf version='1.4'>
  <model name='ecm'>
    <link name='ecm_yaw_link'>
      <pose>-0.6 0.1 0 -1.57079 -0 -1.57079</pose>
      <inertial>
        <pose>0 0 0.603 0 0 -1.57079</pose>
        <mass>0.01</mass>
        <inertia>
          <ixx>1</ixx>
          <ixy>0</ixy>
          <ixz>0</ixz>
          <iyy>1</iyy>
          <iyz>0</iyz>
          <izz>1</izz>
        </inertia>
      </inertial>
      <collision name='ecm_yaw_link_collision'>
        <pose>0 0 0.603 0 0 -1.57079</pose>
        <geometry>
          <mesh>
            <scale>1 1 1</scale>
            <uri>model://dvrk_model/meshes/ecm/Endo_Link_5.STL</uri>
          </mesh>
        </geometry>
      </collision>
      <visual name='ecm_yaw_link_visual'>
        <pose>0 0 0.603 0 0 -1.57079</pose>
        <geometry>
          <mesh>
            <scale>1 1 1</scale>
            <uri>model://dvrk_model/meshes/ecm/Endo_Link_5.STL</uri>
          </mesh>
        </geometry>
      </visual>
      <velocity_decay>
        <linear>0</linear>
        <angular>0</angular>
      </velocity_decay>
    </link>
    <joint name='outer_yaw' type='revolute'>
      <child>ecm_yaw_link</child>
      <parent>world</parent>
      <axis>
        <xyz>1 1.32679e-06 1.32679e-06</xyz>
        <limit>
          <lower>-1.309</lower>
          <upper>0.785397</upper>
          <effort>50</effort>
          <velocity>2</velocity>
        </limit>
        <dynamics/>
      </axis>
    </joint>
    <link name='ecm_pitch_link_1'>
      <pose>-0.222 0.100001 5.01528e-07 -3.14159 -1.32679e-06 -8.70278e-18</pose>
      <inertial>
        <pose>0 0 0 3.14159 -0 1.37008</pose>
        <mass>0.01</mass>
        <inertia>
          <ixx>1</ixx>
          <ixy>0</ixy>
          <ixz>0</ixz>
          <iyy>1</iyy>
          <iyz>0</iyz>
          <izz>1</izz>
        </inertia>
      </inertial>
      <collision name='ecm_pitch_link_1_collision'>
        <pose>0 0 0 3.14159 -0 1.37008</pose>
        <geometry>
          <mesh>
            <scale>1 1 1</scale>
            <uri>model://dvrk_model/meshes/ecm/Endo_Link_5_2.STL</uri>
          </mesh>
        </geometry>
      </collision>
      <visual name='ecm_pitch_link_1_visual'>
        <pose>0 0 0 3.14159 -0 1.37008</pose>
        <geometry>
          <mesh>
            <scale>1 1 1</scale>
            <uri>model://dvrk_model/meshes/ecm/Endo_Link_5_2.STL</uri>
          </mesh>
        </geometry>
      </visual>
      <velocity_decay>
        <linear>0</linear>
        <angular>0</angular>
      </velocity_decay>
    </link>
    <joint name='outer_pitch_0' type='revolute'>
      <child>ecm_pitch_link_1</child>
      <parent>ecm_yaw_link</parent>
      <axis>
        <xyz>1.32679e-06 1.3268e-06 -1</xyz>
        <limit>
          <lower>-1e+16</lower>
          <upper>1e+16</upper>
        </limit>
        <dynamics/>
      </axis>
    </joint>
    <link name='ecm_pitch_link_2'>
      <pose>-0.166137 -0.174574 2.11342e-07 -3.14159 -1.32679e-06 -8.70278e-18</pose>
      <inertial>
        <pose>0 0 -0.0225 0 -0 0</pose>
        <mass>0.01</mass>
        <inertia>
          <ixx>1</ixx>
          <ixy>0</ixy>
          <ixz>0</ixz>
          <iyy>1</iyy>
          <iyz>0</iyz>
          <izz>1</izz>
        </inertia>
      </inertial>
      <collision name='ecm_pitch_link_2_collision'>
        <pose>0 0 -0.0225 0 -0 0</pose>
        <geometry>
          <mesh>
            <scale>1 1 1</scale>
            <uri>model://dvrk_model/meshes/ecm/Endo_Link_6_2.STL</uri>
          </mesh>
        </geometry>
      </collision>
      <visual name='ecm_pitch_link_2_visual'>
        <pose>0 0 -0.0225 0 -0 0</pose>
        <geometry>
          <mesh>
            <scale>1 1 1</scale>
            <uri>model://dvrk_model/meshes/ecm/Endo_Link_6_2.STL</uri>
          </mesh>
        </geometry>
      </visual>
      <velocity_decay>
        <linear>0</linear>
        <angular>0</angular>
      </velocity_decay>
    </link>
    <joint name='outer_pitch_1' type='revolute'>
      <child>ecm_pitch_link_2</child>
      <parent>ecm_pitch_link_1</parent>
      <axis>
        <xyz>1.32679e-06 1.3268e-06 -1</xyz>
        <limit>
          <lower>-1e+16</lower>
          <upper>1e+16</upper>
        </limit>
        <dynamics/>
      </axis>
    </joint>
    <link name='ecm_pitch_link_3'>
      <pose>-0.506137 -0.174574 -2.39768e-07 -3.14159 -1.32679e-06 -8.70278e-18</pose>
      <inertial>
        <pose>0 0 0.025 0 0 -1.57079</pose>
        <mass>0.01</mass>
        <inertia>
          <ixx>1</ixx>
          <ixy>0</ixy>
          <ixz>0</ixz>
          <iyy>1</iyy>
          <iyz>0</iyz>
          <izz>1</izz>
        </inertia>
      </inertial>
      <collision name='ecm_pitch_link_3_collision'>
        <pose>0 0 0.025 0 0 -1.57079</pose>
        <geometry>
          <mesh>
            <scale>1 1 1</scale>
            <uri>model://dvrk_model/meshes/ecm/Endo_Link_7.STL</uri>
          </mesh>
        </geometry>
      </collision>
      <visual name='ecm_pitch_link_3_visual'>
        <pose>0 0 0.025 0 0 -1.57079</pose>
        <geometry>
          <mesh>
            <scale>1 1 1</scale>
            <uri>model://dvrk_model/meshes/ecm/Endo_Link_7.STL</uri>
          </mesh>
        </geometry>
      </visual>
      <velocity_decay>
        <linear>0</linear>
        <angular>0</angular>
      </velocity_decay>
    </link>
    <joint name='outer_pitch_2' type='revolute'>
      <child>ecm_pitch_link_3</child>
      <parent>ecm_pitch_link_2</parent>
      <axis>
        <xyz>1.32679e-06 1.3268e-06 -1</xyz>
        <limit>
          <lower>-1e+16</lower>
          <upper>1e+16</upper>
        </limit>
        <dynamics/>
      </axis>
    </joint>
  </model>
</sdf>
