<?xml version="1.0" encoding="utf-8"?>
<robot name="dvrk_psm" xmlns:xacro="http://www.ros.org/wiki/xacro">

  <xacro:macro name="psm" params="prefix parent">

     <joint name="${prefix}rev_joint" type="continuous">
      <parent link="C_A${parent}_L4"/>
      <child link="${prefix}rev_base_link"/>
      <origin rpy="0 0 0" xyz="0 0.3479 -0.0495"/>   
      <axis xyz="0 0 -1"/>	
     </joint>

     <link name="${prefix}rev_base_link">   
     </link>

     <joint name="${prefix}rev_fixed_joint" type="fixed">
      <parent link="${prefix}rev_base_link"/>
      <child link="${prefix}remote_center_link"/>
      <origin rpy="0 3.1416 0" xyz="0 0.4864 0"/>   
     </joint>

    <!-- fixed joint -->
<!--    <joint name="${prefix}fixed_joint" type="fixed">
      <parent link="${parent_link}"/>
      <child link="${prefix}remote_center_link"/>
      <origin rpy="${rpy}" xyz="${xyz}"/>
    </joint>-->

    <!-- link rc: remote centre link -->
    <link name="${prefix}remote_center_link" />   

    <!-- fixed joint -->
    <joint name="${prefix}rc_fixed_joint" type="fixed">
      <parent link="${prefix}remote_center_link"/>
      <child link="${prefix}psm_base_link"/>
      <origin rpy="0 0 0" xyz="0 -0.369 0"/>
    </joint>

    <!-- link 0: psm base link -->
    <link name="${prefix}psm_base_link">
    <inertial>
      <mass value="0.01"/>
      <origin rpy="1.5708 0 3.1416" xyz="0.039 -0.03888 -0.07879"/>
      <inertia ixx="1.0" ixy="0.0" ixz="0.0" iyy="1.0" iyz="0.0" izz="1.0"/>
    </inertial>
      
      <visual>
        <origin rpy="1.5708 0 3.1416" xyz="0.039 -0.03888 -0.07879"/>
        <geometry>
          <mesh filename="package://dvrk_model/meshes/psm/psm_base.dae"/>      
        </geometry>
      </visual>
	<collision>
        <origin rpy="1.5708 0 3.1416" xyz="0.039 -0.03888 -0.07879"/>
        <geometry>
          <mesh filename="package://dvrk_model/meshes/psm/psm_base.dae"/>      
        </geometry>
      </collision>
    </link>
    
    <!-- link 1: outer_yaw -->
    <link name="${prefix}outer_yaw_link">


    <inertial>
      <mass value="0.01"/>
      <origin rpy="3.1416 0 1.5708" xyz="0.0125 0 0.1575"/>
      <inertia ixx="1.0" ixy="0.0" ixz="0.0" iyy="1.0" iyz="0.0" izz="1.0"/>
    </inertial>

      <visual>
         <origin rpy="0 0 -1.5708" xyz="0.0125 0 0.1575"/> 
        <!--<origin rpy="3.1416 0 1.5708" xyz="0.0125 0 0.1575"/> -->
        <geometry>
          <mesh filename="package://dvrk_model/meshes/psm/outer_yaw.dae"/>      
        </geometry>
      </visual>

      <collision>
        <!-- <origin rpy="0 0 -1.5708" xyz="0.0125 0 0.1575"/> -->
        <origin rpy="3.1416 0 1.5708" xyz="0.0125 0 0.1575"/>
        <geometry>
          <mesh filename="package://dvrk_model/meshes/psm/outer_yaw.dae"/>      
        </geometry>
      </collision>
    </link>
    
    <!-- link 2-1: outer_pitch_back -->
    <link name="${prefix}outer_pitch_back_link">

    <inertial>
      <mass value="0.1"/>
      <origin rpy="0 0 -0.27129" xyz="0 0 0"/>
      <inertia ixx="1.0" ixy="0.0" ixz="0.0" iyy="1.0" iyz="0.0" izz="1.0"/>
    </inertial>
      <visual>
        <origin rpy="0 0 -0.27129" xyz="0 0 0"/>
        <geometry>
          <mesh filename="package://dvrk_model/meshes/psm/outer_pitch_back.dae"/>      
        </geometry>
      </visual>
    <collision>
        <origin rpy="0 0 -0.27129" xyz="0 0 0"/>
        <geometry>
          <mesh filename="package://dvrk_model/meshes/psm/outer_pitch_back.dae"/>      
        </geometry>
    </collision>

    </link>

    <link name="${prefix}outer_pitch_bottom_link"/>

    <link name="${prefix}outer_pitch_front_link"/>

    <link name="${prefix}outer_pitch_top_link"/>

    <link name="${prefix}outer_insertion_link"/>

    <link name="${prefix}tool_main_link"/>

    <joint name="${prefix}outer_yaw_joint" type="revolute">
      <parent link="${prefix}psm_base_link"/>
      <child link="${prefix}outer_yaw_link"/>
      <axis xyz="0 0 1"/>
      <origin rpy="1.5708 -1.5708 0" xyz="0.0 0.0 0.0"/>
      <limit lower="-1.5707" upper="1.5707" velocity=".4" effort="1000"/>
    </joint>


    <joint name="${prefix}outer_pitch_joint_1" type="revolute">
      <parent link="${prefix}outer_yaw_link"/>
      <child link="${prefix}outer_pitch_back_link"/>
      <axis xyz="0 0 1"/>
      <origin rpy="-1.5708 -1.5708 0" xyz="0 0.0295 0.1495"/>
      <limit lower="-1.5708" upper="1.5708" velocity=".4" effort="1000"/>	
    </joint>

    <joint name="${prefix}outer_pitch_joint_2" type="revolute">
      <parent link="${prefix}outer_pitch_back_link"/>
      <child link="${prefix}outer_pitch_bottom_link"/>
      <limit lower="-1.5708" upper="1.5708" velocity=".4" effort="1000"/>
    </joint>
        
    <joint name="${prefix}outer_pitch_joint_3" type="revolute">
      <parent link="${prefix}outer_yaw_link"/>
      <child link="${prefix}outer_pitch_front_link"/>
      <limit lower="-1.5708" upper="1.5708" velocity=".4" effort="1000"/>
    </joint>

    <joint name="${prefix}outer_pitch_joint_4" type="revolute">
      <parent link="${prefix}outer_pitch_front_link"/>
      <child link="${prefix}outer_pitch_bottom_link"/>
      <limit lower="-1.5708" upper="1.5708" velocity=".4" effort="1000"/>
    </joint>

    <joint name="${prefix}outer_pitch_joint_5" type="revolute">
      <parent link="${prefix}outer_pitch_back_link"/>
      <child link="${prefix}outer_pitch_top_link"/>
      <limit lower="-1.5708" upper="1.5708" velocity=".4" effort="1000"/>
    </joint>

<!--    <joint name="${prefix}outer_pitch_joint_6" type="revolute">
      <parent link="${prefix}outer_pitch_front_link"/>
      <child link="${prefix}outer_pitch_top_link"/>
      <limit lower="-1.5708" upper="1.5708" velocity=".4" effort="1000"/>
    </joint>-->

    <joint name="${prefix}outer_pitch_joint_7" type="revolute">
      <parent link="${prefix}outer_pitch_bottom_link"/>
      <child link="${prefix}outer_insertion_link"/>
      <limit lower="-1.5708" upper="1.5708" velocity=".4" effort="1000"/>
    </joint>

    <joint name="${prefix}outer_pitch_joint_8" type="revolute">
      <parent link="${prefix}outer_pitch_top_link"/>
      <child link="${prefix}outer_insertion_link"/>
      <limit lower="-1.5708" upper="1.5708" velocity=".4" effort="1000"/>
    </joint>

    <joint name="${prefix}outer_insertion_joint" type="prismatic">
      <parent link="${prefix}outer_insertion_link"/>
      <child link="${prefix}tool_main_link"/>
      <limit lower="0" upper="0.240" velocity=".4" effort="1000"/>
    </joint>

    <transmission name="tran1">
      <type>transmission_interface/SimpleTransmission</type>
      <joint name="${prefix}outer_yaw_joint">
	<hardwareInterface>EffortJointInterface</hardwareInterface>
      </joint>
      <actuator name="motor1">
        <hardwareInterface>EffortJointInterface</hardwareInterface>
        <mechanicalReduction>1</mechanicalReduction>
      </actuator>
    </transmission>

    <transmission name="tran2">
      <type>transmission_interface/SimpleTransmission</type>
      <joint name="${prefix}outer_pitch_joint_1">
	<hardwareInterface>EffortJointInterface</hardwareInterface>
      </joint>
      <actuator name="motor2">
        <hardwareInterface>EffortJointInterface</hardwareInterface>
        <mechanicalReduction>1</mechanicalReduction>
      </actuator>
    </transmission>

    <transmission name="tran3">
      <type>transmission_interface/SimpleTransmission</type>
      <joint name="${prefix}outer_insertion_joint">
	<hardwareInterface>EffortJointInterface</hardwareInterface>
      </joint>
      <actuator name="motor3">
        <hardwareInterface>EffortJointInterface</hardwareInterface>
        <mechanicalReduction>1</mechanicalReduction>
      </actuator>
    </transmission>


  </xacro:macro>  
</robot>
