<sdf version='1.6'>
  <model name='ecm'>
    <link name='base_link'>
      <pose frame=''>0 0 0 0 -0 0</pose>
      <inertial>
        <pose frame=''>-0.003775 -3e-05 0.069014 0 -0 0</pose>
        <mass>2.64078</mass>
        <inertia>
          <ixx>4.76582e-06</ixx>
          <ixy>-8.19632e-08</ixy>
          <ixz>-9.01608e-05</ixz>
          <iyy>0.00171045</iyy>
          <iyz>-4.3325e-09</iyz>
          <izz>0.00170568</izz>
        </inertia>
      </inertial>
      <collision name='base_link_collision'>
        <pose frame=''>0 0 0 0 -0 0</pose>
        <geometry>
          <mesh>
            <scale>1 1 1</scale>
            <uri>model://ECM//meshes/base_link.STL</uri>
          </mesh>
        </geometry>
      </collision>
      <collision name='base_link_fixed_joint_lump__remote_center_link_collision_1'>
        <pose frame=''>0.612599 0 0.101595 -0 0 -1.5708</pose>
        <geometry>
          <mesh>
            <scale>1 1 1</scale>
            <uri>model://ECM//meshes/remote_center_link.STL</uri>
          </mesh>
        </geometry>
      </collision>
      <visual name='base_link_visual'>
        <pose frame=''>0 0 0 0 -0 0</pose>
        <geometry>
          <mesh>
            <scale>1 1 1</scale>
            <uri>model://ECM//meshes/base_link.STL</uri>
          </mesh>
        </geometry>
      </visual>
      <visual name='base_link_fixed_joint_lump__remote_center_link_visual_1'>
        <pose frame=''>0.612599 0 0.101595 -0 0 -1.5708</pose>
        <geometry>
          <mesh>
            <scale>1 1 1</scale>
            <uri>model://ECM//meshes/remote_center_link.STL</uri>
          </mesh>
        </geometry>
      </visual>
    </link>
    <link name='yaw_link'>
      <pose frame=''>0.0732 0 0.10146 1.5708 -0 1.5708</pose>
      <inertial>
        <pose frame=''>0 -0.029045 0.10669 0 -0 0</pose>
        <mass>6.4168</mass>
        <inertia>
          <ixx>0.00086598</ixx>
          <ixy>7.8532e-10</ixy>
          <ixz>2.5709e-09</ixz>
          <iyy>0.0016561</iyy>
          <iyz>-0.00015825</iyz>
          <izz>0.00085001</izz>
        </inertia>
      </inertial>
      <collision name='yaw_link_collision'>
        <pose frame=''>0 0 0 0 -0 0</pose>
        <geometry>
          <mesh>
            <scale>1 1 1</scale>
            <uri>model://ECM//meshes/yaw_link.STL</uri>
          </mesh>
        </geometry>
      </collision>
      <visual name='yaw_link_visual'>
        <pose frame=''>0 0 0 0 -0 0</pose>
        <geometry>
          <mesh>
            <scale>1 1 1</scale>
            <uri>model://ECM//meshes/yaw_link.STL</uri>
          </mesh>
        </geometry>
      </visual>
    </link>
    <joint name='yaw_joint' type='revolute'>
      <child>yaw_link</child>
      <parent>base_link</parent>
      <axis>
        <xyz>1 0 -0</xyz>
        <limit>
          <lower>-1e+16</lower>
          <upper>1e+16</upper>
        </limit>
        <dynamics>
          <spring_reference>0</spring_reference>
          <spring_stiffness>0</spring_stiffness>
        </dynamics>
        <use_parent_model_frame>1</use_parent_model_frame>
      </axis>
    </joint>
    <link name='pitch_back_link'>
      <pose frame=''>0.23563 0 0.09166 -1.57239 0 0</pose>
      <inertial>
        <pose frame=''>-0.032853 -0.14997 -0.008061 0 -0 0</pose>
        <mass>0.4214</mass>
        <inertia>
          <ixx>0</ixx>
          <ixy>0</ixy>
          <ixz>0</ixz>
          <iyy>0</iyy>
          <iyz>0</iyz>
          <izz>0</izz>
        </inertia>
      </inertial>
      <collision name='pitch_back_link_collision'>
        <pose frame=''>0 0 0 0 -0 0</pose>
        <geometry>
          <mesh>
            <scale>1 1 1</scale>
            <uri>model://ECM//meshes/pitch_back_link.STL</uri>
          </mesh>
        </geometry>
      </collision>
      <visual name='pitch_back_link_visual'>
        <pose frame=''>0 0 0 0 -0 0</pose>
        <geometry>
          <mesh>
            <scale>1 1 1</scale>
            <uri>model://ECM//meshes/pitch_back_link.STL</uri>
          </mesh>
        </geometry>
      </visual>
    </link>
    <joint name='pitch_back_joint' type='revolute'>
      <child>pitch_back_link</child>
      <parent>yaw_link</parent>
      <axis>
        <xyz>-0 0.999999 -0.001593</xyz>
        <limit>
          <lower>-1e+16</lower>
          <upper>1e+16</upper>
        </limit>
        <dynamics>
          <spring_reference>0</spring_reference>
          <spring_stiffness>0</spring_stiffness>
        </dynamics>
        <use_parent_model_frame>1</use_parent_model_frame>
      </axis>
    </joint>
    <link name='pitch_front_link'>
      <pose frame=''>0.2722 0 0.10146 -1.57239 0 0</pose>
      <inertial>
        <pose frame=''>-0.030619 -0.13578 -0 0 -0 0</pose>
        <mass>1.6069</mass>
        <inertia>
          <ixx>0</ixx>
          <ixy>0</ixy>
          <ixz>0</ixz>
          <iyy>0</iyy>
          <iyz>0</iyz>
          <izz>0</izz>
        </inertia>
      </inertial>
      <collision name='pitch_front_link_collision'>
        <pose frame=''>0 0 0 0 -0 0</pose>
        <geometry>
          <mesh>
            <scale>1 1 1</scale>
            <uri>model://ECM//meshes/pitch_front_link.STL</uri>
          </mesh>
        </geometry>
      </collision>
      <visual name='pitch_front_link_visual'>
        <pose frame=''>0 0 0 0 -0 0</pose>
        <geometry>
          <mesh>
            <scale>1 1 1</scale>
            <uri>model://ECM//meshes/pitch_front_link.STL</uri>
          </mesh>
        </geometry>
      </visual>
    </link>
    <joint name='pitch_front_joint' type='revolute'>
      <child>pitch_front_link</child>
      <parent>yaw_link</parent>
      <axis>
        <xyz>-0 0.999999 -0.001593</xyz>
        <limit>
          <lower>-1e+16</lower>
          <upper>1e+16</upper>
        </limit>
        <dynamics>
          <spring_reference>0</spring_reference>
          <spring_stiffness>0</spring_stiffness>
        </dynamics>
        <use_parent_model_frame>1</use_parent_model_frame>
      </axis>
    </joint>
    <link name='pitch_bottom_link'>
      <pose frame=''>0.169199 0.000457 0.388265 -1.57239 0 0</pose>
      <inertial>
        <pose frame=''>0.14594 -0.026715 -0.000165 0 -0 0</pose>
        <mass>0.35928</mass>
        <inertia>
          <ixx>0.00023901</ixx>
          <ixy>0.00022767</ixy>
          <ixz>-3.8706e-06</ixz>
          <iyy>0.0030096</iyy>
          <iyz>-7.279e-07</iyz>
          <izz>0.0029617</izz>
        </inertia>
      </inertial>
      <collision name='pitch_bottom_link_collision'>
        <pose frame=''>0 0 0 0 -0 0</pose>
        <geometry>
          <mesh>
            <scale>1 1 1</scale>
            <uri>model://ECM//meshes/pitch_bottom_link.STL</uri>
          </mesh>
        </geometry>
      </collision>
      <visual name='pitch_bottom_link_visual'>
        <pose frame=''>0 0 0 0 -0 0</pose>
        <geometry>
          <mesh>
            <scale>1 1 1</scale>
            <uri>model://ECM//meshes/pitch_bottom_link.STL</uri>
          </mesh>
        </geometry>
      </visual>
    </link>
    <joint name='pitch_bottom_joint' type='revolute'>
      <child>pitch_bottom_link</child>
      <parent>pitch_front_link</parent>
      <axis>
        <xyz>-0 0.999999 -0.001593</xyz>
        <limit>
          <lower>-1e+16</lower>
          <upper>1e+16</upper>
        </limit>
        <dynamics>
          <spring_reference>0</spring_reference>
          <spring_stiffness>0</spring_stiffness>
        </dynamics>
        <use_parent_model_frame>1</use_parent_model_frame>
      </axis>
    </joint>
    <link name='pitch_end_link'>
      <pose frame=''>0.509599 0.000457 0.3884 -1.57239 0 0</pose>
      <inertial>
        <pose frame=''>0.018122 -0.027143 0.000789 0 -0 0</pose>
        <mass>2.0321</mass>
        <inertia>
          <ixx>0</ixx>
          <ixy>0</ixy>
          <ixz>0</ixz>
          <iyy>0</iyy>
          <iyz>0</iyz>
          <izz>0</izz>
        </inertia>
      </inertial>
      <collision name='pitch_end_link_collision'>
        <pose frame=''>0 0 0 0 -0 0</pose>
        <geometry>
          <mesh>
            <scale>1 1 1</scale>
            <uri>model://ECM//meshes/pitch_end_link.STL</uri>
          </mesh>
        </geometry>
      </collision>
      <visual name='pitch_end_link_visual'>
        <pose frame=''>0 0 0 0 -0 0</pose>
        <geometry>
          <mesh>
            <scale>1 1 1</scale>
            <uri>model://ECM//meshes/pitch_end_link.STL</uri>
          </mesh>
        </geometry>
      </visual>
    </link>
    <joint name='pitch_end_joint' type='revolute'>
      <child>pitch_end_link</child>
      <parent>pitch_bottom_link</parent>
      <axis>
        <xyz>-0 0.999999 -0.001593</xyz>
        <limit>
          <lower>-1e+16</lower>
          <upper>1e+16</upper>
        </limit>
        <dynamics>
          <spring_reference>0</spring_reference>
          <spring_stiffness>0</spring_stiffness>
        </dynamics>
        <use_parent_model_frame>1</use_parent_model_frame>
      </axis>
    </joint>
    <link name='main_insertion_link'>
      <pose frame=''>0.551599 0.000594 0.474543 3.14 0 0</pose>
      <inertial>
        <pose frame=''>0.008617 -0.000792 -0.047928 0 -0 0</pose>
        <mass>0.23108</mass>
        <inertia>
          <ixx>0</ixx>
          <ixy>0</ixy>
          <ixz>0</ixz>
          <iyy>0</iyy>
          <iyz>0</iyz>
          <izz>0</izz>
        </inertia>
      </inertial>
      <collision name='main_insertion_link_collision'>
        <pose frame=''>0 0 0 0 -0 0</pose>
        <geometry>
          <mesh>
            <scale>1 1 1</scale>
            <uri>model://ECM//meshes/main_insertion_link.STL</uri>
          </mesh>
        </geometry>
      </collision>
      <visual name='main_insertion_link_visual'>
        <pose frame=''>0 0 0 0 -0 0</pose>
        <geometry>
          <mesh>
            <scale>1 1 1</scale>
            <uri>model://ECM//meshes/main_insertion_link.STL</uri>
          </mesh>
        </geometry>
      </visual>
    </link>
    <joint name='main_insertion_joint' type='prismatic'>
      <child>main_insertion_link</child>
      <parent>pitch_end_link</parent>
      <axis>
        <!-- <xyz>-0 -0.001596 -0.999999</xyz> -->
        <xyz> 0 0 1</xyz>
        <limit>
          <lower>0</lower>
          <upper>0.35</upper>
          <effort>50</effort>
          <velocity>100</velocity>
        </limit>
        <dynamics>
          <spring_reference>0</spring_reference>
          <spring_stiffness>0</spring_stiffness>
        </dynamics>
        <!-- <use_parent_model_frame>1</use_parent_model_frame> -->
      </axis>
    </joint>
    <link name='tool_link'>
      <pose frame=''>0.612599 0.000594 0.474543 3.14 0 0</pose>
      <inertial>
        <pose frame=''>0 -0.000793 -0.10732 0 -0 0</pose>
        <mass>1.9074</mass>
        <inertia>
          <ixx>0</ixx>
          <ixy>0</ixy>
          <ixz>0</ixz>
          <iyy>0</iyy>
          <iyz>0</iyz>
          <izz>0</izz>
        </inertia>
      </inertial>
      <collision name='tool_link_collision'>
        <pose frame=''>0 0 0 0 -0 0</pose>
        <geometry>
          <mesh>
            <scale>1 1 1</scale>
            <uri>model://ECM//meshes/tool_link.STL</uri>
          </mesh>
        </geometry>
      </collision>
      <visual name='tool_link_visual'>
        <pose frame=''>0 0 0 0 -0 0</pose>
        <geometry>
          <mesh>
            <scale>1 1 1</scale>
            <uri>model://ECM//meshes/tool_link.STL</uri>
          </mesh>
        </geometry>
      </visual>
    </link>
    <joint name='tool_joint' type='revolute'>
      <child>tool_link</child>
      <parent>main_insertion_link</parent>
      <axis>
        <!-- <xyz>0 0.001596 0.999999</xyz> -->
        <xyz>0 0 1</xyz>
        <limit>
          <lower>-1e+16</lower>
          <upper>1e+16</upper>
        </limit>
        <dynamics>
          <spring_reference>0</spring_reference>
          <spring_stiffness>0</spring_stiffness>
        </dynamics>
        <!-- <use_parent_model_frame>1</use_parent_model_frame> -->
      </axis>
    </joint>
    <link name='pitch_top_link'>
      <pose frame=''>0.163728 0.000516 0.425717 -1.57239 0 0</pose>
      <inertial>
        <pose frame=''>0.1702 -6.8e-05 0.000793 0 -0 0</pose>
        <mass>0.43851</mass>
        <inertia>
          <ixx>0</ixx>
          <ixy>0</ixy>
          <ixz>0</ixz>
          <iyy>0</iyy>
          <iyz>0</iyz>
          <izz>0</izz>
        </inertia>
      </inertial>
      <collision name='pitch_top_link_collision'>
        <pose frame=''>0 0 0 0 -0 0</pose>
        <geometry>
          <mesh>
            <scale>1 1 1</scale>
            <uri>model://ECM//meshes/pitch_top_link.STL</uri>
          </mesh>
        </geometry>
      </collision>
      <visual name='pitch_top_link_visual'>
        <pose frame=''>0 0 0 0 -0 0</pose>
        <geometry>
          <mesh>
            <scale>1 1 1</scale>
            <uri>model://ECM//meshes/pitch_top_link.STL</uri>
          </mesh>
        </geometry>
      </visual>
    </link>
    <joint name='pitch_top_joint' type='revolute'>
      <child>pitch_top_link</child>
      <parent>pitch_front_link</parent>
      <axis>
        <xyz>-0 0.999999 -0.001593</xyz>
        <limit>
          <lower>-1e+16</lower>
          <upper>1e+16</upper>
        </limit>
        <dynamics>
          <spring_reference>0</spring_reference>
          <spring_stiffness>0</spring_stiffness>
        </dynamics>
        <use_parent_model_frame>1</use_parent_model_frame>
      </axis>
    </joint>
    <joint name='pitch_bottom_back_joint' type='revolute'>
      <child>pitch_bottom_link</child>
      <parent>pitch_back_link</parent>
      <pose> -0.0365687 0.0097841 0 0 0 0</pose>
      <axis>
        <xyz>-0 0.999999 -0.001593</xyz>
        <limit>
          <lower>-1e+16</lower>
          <upper>1e+16</upper>
        </limit>
        <dynamics>
          <spring_reference>0</spring_reference>
          <spring_stiffness>0</spring_stiffness>
        </dynamics>
        <use_parent_model_frame>1</use_parent_model_frame>
      </axis>
    </joint>
    <joint name='pitch_top_end_joint' type='revolute'>
      <child>pitch_end_link</child>
      <parent>pitch_top_link</parent>
      <pose> -0.0045766 -0.0375723 0 0 0 0</pose>
      <axis>
        <xyz>-0 0.999999 -0.001593</xyz>
        <limit>
          <lower>-1e+16</lower>
          <upper>1e+16</upper>
        </limit>
        <dynamics>
          <spring_reference>0</spring_reference>
          <spring_stiffness>0</spring_stiffness>
        </dynamics>
        <use_parent_model_frame>1</use_parent_model_frame>
      </axis>
    </joint>
    <plugin name='dvrk_plugins' filename='libdvrk_plugins.so'/>
  </model>
</sdf>
